Workbook

Sheet Resumen
A1: Resumen de seguimiento de PV
A2: Hoy: | B2: =TODAY() -> 46304
A3: Fecha de corte (opcional): | B3: 46235 | C3: Si la fecha de entrega (estimada o reprogramada) es anterior a este corte y no está marcada ✔, el Estado dice REVISAR. Cámbiala o bórrala.
A5: 1. Resumen por estado | I5: 2. Pendientes (sin ✔)
A6: Estado | B6: Partidas | C6: % del total | D6: PV distintos | I6: Concepto | J6: Valor
A7: ATRASADO | B7: =COUNTIF('Lista PV'!$M$2:$M$826,A7) -> 173 | C7: =IF($B$13=0,0,B7/$B$13) -> 0.20969697 | D7: =SUMPRODUCT(('Lista PV'!$M$2:$M$826=A7)/COUNTIFS('Lista PV'!$A$2:$A$826,'Lista PV'!$A$2:$A$826,'Lista PV'!$M$2:$M$826,'Lista PV'!$M$2:$M$826)) -> 65 | I7: Partidas pendientes de entrega | J7: =B13-B12 -> 240
A8: POR VENCER | B8: =COUNTIF('Lista PV'!$M$2:$M$826,A8) -> 18 | C8: =IF($B$13=0,0,B8/$B$13) -> 0.021818182 | D8: =SUMPRODUCT(('Lista PV'!$M$2:$M$826=A8)/COUNTIFS('Lista PV'!$A$2:$A$826,'Lista PV'!$A$2:$A$826,'Lista PV'!$M$2:$M$826,'Lista PV'!$M$2:$M$826)) -> 5 | I8: Partidas con atraso (rojo) | J8: =COUNTIF('Lista PV'!$K$2:$K$826,">0") -> 173
A9: EN TIEMPO | B9: =COUNTIF('Lista PV'!$M$2:$M$826,A9) -> 48 | C9: =IF($B$13=0,0,B9/$B$13) -> 0.058181818 | D9: =SUMPRODUCT(('Lista PV'!$M$2:$M$826=A9)/COUNTIFS('Lista PV'!$A$2:$A$826,'Lista PV'!$A$2:$A$826,'Lista PV'!$M$2:$M$826,'Lista PV'!$M$2:$M$826)) -> 15 | I9: Atraso promedio (días) | J9: =IFERROR(AVERAGE('Lista PV'!$K$2:$K$826),0) -> 32.138728
A10: REVISAR | B10: =COUNTIF('Lista PV'!$M$2:$M$826,A10) -> 0 | C10: =IF($B$13=0,0,B10/$B$13) -> 0 | D10: =SUMPRODUCT(('Lista PV'!$M$2:$M$826=A10)/COUNTIFS('Lista PV'!$A$2:$A$826,'Lista PV'!$A$2:$A$826,'Lista PV'!$M$2:$M$826,'Lista PV'!$M$2:$M$826)) -> 0 | I10: Atraso máximo (días) | J10: =MAX('Lista PV'!$K$2:$K$826) -> 61
A11: REVISAR TE | B11: =COUNTIF('Lista PV'!$M$2:$M$826,A11) -> 1 | C11: =IF($B$13=0,0,B11/$B$13) -> 0.0012121212 | D11: =SUMPRODUCT(('Lista PV'!$M$2:$M$826=A11)/COUNTIFS('Lista PV'!$A$2:$A$826,'Lista PV'!$A$2:$A$826,'Lista PV'!$M$2:$M$826,'Lista PV'!$M$2:$M$826)) -> 1 | I11: Vencen en los próximos 7 días | J11: =COUNTIFS('Lista PV'!$M$2:$M$826,"POR VENCER")+COUNTIFS('Lista PV'!$M$2:$M$826,"EN TIEMPO",'Lista PV'!$Q$2:$Q$826,"<="&$B$2+7,'Lista PV'!$Q$2:$Q$826,">="&$B$2)+COUNTIFS('Lista PV'!$M$2:$M$826,"EN TIEMPO",'Lista PV'!$Q$2:$Q$826,"",'Lista PV'!$I$2:$I$826,"<="&$B$2+7,'Lista PV'!$I$2:$I$826,">="&$B$2) -> 26
A12: Entregado | B12: =COUNTIF('Lista PV'!$M$2:$M$826,A12) -> 585 | C12: =IF($B$13=0,0,B12/$B$13) -> 0.70909091 | D12: =SUMPRODUCT(('Lista PV'!$M$2:$M$826=A12)/COUNTIFS('Lista PV'!$A$2:$A$826,'Lista PV'!$A$2:$A$826,'Lista PV'!$M$2:$M$826,'Lista PV'!$M$2:$M$826)) -> 217
A13: TOTAL | B13: =SUM(B7:B12) -> 825 | C13: =SUM(C7:C12) -> 1 | D13: =SUMPRODUCT(1/COUNTIF('Lista PV'!$A$2:$A$826,'Lista PV'!$A$2:$A$826)) -> 302
A14: Reprogramadas | B14: =SUMPRODUCT(('Lista PV'!$Q$2:$Q$826<>"")*('Lista PV'!$Q$2:$Q$826<>'Lista PV'!$I$2:$I$826)) -> 11
A15: Un PV puede tener partidas en varios estados, por eso "PV distintos" por estado puede sumar más que el total.
A18: 3. Antigüedad del atraso (partidas con días de atraso) | I18: 4. Datos por capturar / completar
A19: Rango (días de atraso) | B19: Partidas | C19: % del total con atraso | I19: Columna | J19: Celdas vacías | K19: Para qué
A20: 1 a 7 | B20: =COUNTIFS('Lista PV'!$K$2:$K$826,">=1",'Lista PV'!$K$2:$K$826,"<=7") -> 32 | C20: =IF($B$24=0,0,B20/$B$24) -> 0.1849711 | I20: fecha reprogramada de entrega | J20: =COUNTBLANK('Lista PV'!$Q$2:$Q$826) -> 814 | K20: Solo si se mueve la entrega
A21: 8 a 30 | B21: =COUNTIFS('Lista PV'!$K$2:$K$826,">=8",'Lista PV'!$K$2:$K$826,"<=30") -> 40 | C21: =IF($B$24=0,0,B21/$B$24) -> 0.23121387 | I21: marcar de entregado | J21: =COUNTBLANK('Lista PV'!$L$2:$L$826) -> 240 | K21: Poner un carácter al entregar (✔)
A22: 31 a 60 | B22: =COUNTIFS('Lista PV'!$K$2:$K$826,">=31",'Lista PV'!$K$2:$K$826,"<=60") -> 99 | C22: =IF($B$24=0,0,B22/$B$24) -> 0.57225434 | I22: Cliente | J22: =COUNTBLANK('Lista PV'!$B$2:$B$826) -> 59 | K22: Completar en Lista PV
A23: Más de 60 | B23: =COUNTIFS('Lista PV'!$K$2:$K$826,">=61",'Lista PV'!$K$2:$K$826,"<=99999") -> 2 | C23: =IF($B$24=0,0,B23/$B$24) -> 0.011560694 | I23: Fecha entrega estimada | J23: =COUNTBLANK('Lista PV'!$I$2:$I$826) -> 44 | K23: Sin TE: estado REVISAR TE
A24: TOTAL | B24: =SUM(B20:B23) -> 173 | C24: =SUM(C20:C23) -> 1
A27: 5. Pendientes por cliente (partidas sin ✔)
A28: Cliente | B28: Atrasado | C28: Por vencer | D28: En tiempo | E28: Revisar | F28: Revisar TE | G28: Total pendientes
A29: TRISTONE FLOWTECH MEXICO | B29: =COUNTIFS('Lista PV'!$B$2:$B$826,$A29,'Lista PV'!$M$2:$M$826,"ATRASADO") -> 54 | C29: =COUNTIFS('Lista PV'!$B$2:$B$826,$A29,'Lista PV'!$M$2:$M$826,"POR VENCER") -> 4 | D29: =COUNTIFS('Lista PV'!$B$2:$B$826,$A29,'Lista PV'!$M$2:$M$826,"EN TIEMPO") -> 19 | E29: =COUNTIFS('Lista PV'!$B$2:$B$826,$A29,'Lista PV'!$M$2:$M$826,"REVISAR") -> 0 | F29: =COUNTIFS('Lista PV'!$B$2:$B$826,$A29,'Lista PV'!$M$2:$M$826,"REVISAR TE") -> 0 | G29: =SUM(B29:F29) -> 77
A30: TOYODA GOSEI RUBBER MEXICO | B30: =COUNTIFS('Lista PV'!$B$2:$B$826,$A30,'Lista PV'!$M$2:$M$826,"ATRASADO") -> 12 | C30: =COUNTIFS('Lista PV'!$B$2:$B$826,$A30,'Lista PV'!$M$2:$M$826,"POR VENCER") -> 4 | D30: =COUNTIFS('Lista PV'!$B$2:$B$826,$A30,'Lista PV'!$M$2:$M$826,"EN TIEMPO") -> 8 | E30: =COUNTIFS('Lista PV'!$B$2:$B$826,$A30,'Lista PV'!$M$2:$M$826,"REVISAR") -> 0 | F30: =COUNTIFS('Lista PV'!$B$2:$B$826,$A30,'Lista PV'!$M$2:$M$826,"REVISAR TE") -> 0 | G30: =SUM(B30:F30) -> 24
A31: AKWEL ORIZABA MEXICO | B31: =COUNTIFS('Lista PV'!$B$2:$B$826,$A31,'Lista PV'!$M$2:$M$826,"ATRASADO") -> 23 | C31: =COUNTIFS('Lista PV'!$B$2:$B$826,$A31,'Lista PV'!$M$2:$M$826,"POR VENCER") -> 9 | D31: =COUNTIFS('Lista PV'!$B$2:$B$826,$A31,'Lista PV'!$M$2:$M$826,"EN TIEMPO") -> 8 | E31: =COUNTIFS('Lista PV'!$B$2:$B$826,$A31,'Lista PV'!$M$2:$M$826,"REVISAR") -> 0 | F31: =COUNTIFS('Lista PV'!$B$2:$B$826,$A31,'Lista PV'!$M$2:$M$826,"REVISAR TE") -> 0 | G31: =SUM(B31:F31) -> 40
A32: MADISEN | B32: =COUNTIFS('Lista PV'!$B$2:$B$826,$A32,'Lista PV'!$M$2:$M$826,"ATRASADO") -> 17 | C32: =COUNTIFS('Lista PV'!$B$2:$B$826,$A32,'Lista PV'!$M$2:$M$826,"POR VENCER") -> 0 | D32: =COUNTIFS('Lista PV'!$B$2:$B$826,$A32,'Lista PV'!$M$2:$M$826,"EN TIEMPO") -> 3 | E32: =COUNTIFS('Lista PV'!$B$2:$B$826,$A32,'Lista PV'!$M$2:$M$826,"REVISAR") -> 0 | F32: =COUNTIFS('Lista PV'!$B$2:$B$826,$A32,'Lista PV'!$M$2:$M$826,"REVISAR TE") -> 0 | G32: =SUM(B32:F32) -> 20
A33: HUTCHINSON TRANSFERENCIA DE FLUIDOS MEXICO | B33: =COUNTIFS('Lista PV'!$B$2:$B$826,$A33,'Lista PV'!$M$2:$M$826,"ATRASADO") -> 10 | C33: =COUNTIFS('Lista PV'!$B$2:$B$826,$A33,'Lista PV'!$M$2:$M$826,"POR VENCER") -> 1 | D33: =COUNTIFS('Lista PV'!$B$2:$B$826,$A33,'Lista PV'!$M$2:$M$826,"EN TIEMPO") -> 1 | E33: =COUNTIFS('Lista PV'!$B$2:$B$826,$A33,'Lista PV'!$M$2:$M$826,"REVISAR") -> 0 | F33: =COUNTIFS('Lista PV'!$B$2:$B$826,$A33,'Lista PV'!$M$2:$M$826,"REVISAR TE") -> 0 | G33: =SUM(B33:F33) -> 12
A34: TI AUTOMOTIVE REYNOSA | B34: =COUNTIFS('Lista PV'!$B$2:$B$826,$A34,'Lista PV'!$M$2:$M$826,"ATRASADO") -> 27 | C34: =COUNTIFS('Lista PV'!$B$2:$B$826,$A34,'Lista PV'!$M$2:$M$826,"POR VENCER") -> 0 | D34: =COUNTIFS('Lista PV'!$B$2:$B$826,$A34,'Lista PV'!$M$2:$M$826,"EN TIEMPO") -> 2 | E34: =COUNTIFS('Lista PV'!$B$2:$B$826,$A34,'Lista PV'!$M$2:$M$826,"REVISAR") -> 0 | F34: =COUNTIFS('Lista PV'!$B$2:$B$826,$A34,'Lista PV'!$M$2:$M$826,"REVISAR TE") -> 0 | G34: =SUM(B34:F34) -> 29
A35: HUTCHINSON AUTOPARTES MEXICO | B35: =COUNTIFS('Lista PV'!$B$2:$B$826,$A35,'Lista PV'!$M$2:$M$826,"ATRASADO") -> 2 | C35: =COUNTIFS('Lista PV'!$B$2:$B$826,$A35,'Lista PV'!$M$2:$M$826,"POR VENCER") -> 0 | D35: =COUNTIFS('Lista PV'!$B$2:$B$826,$A35,'Lista PV'!$M$2:$M$826,"EN TIEMPO") -> 4 | E35: =COUNTIFS('Lista PV'!$B$2:$B$826,$A35,'Lista PV'!$M$2:$M$826,"REVISAR") -> 0 | F35: =COUNTIFS('Lista PV'!$B$2:$B$826,$A35,'Lista PV'!$M$2:$M$826,"REVISAR TE") -> 0 | G35: =SUM(B35:F35) -> 6
A36: COOPER-STANDARD DE MEXICO | B36: =COUNTIFS('Lista PV'!$B$2:$B$826,$A36,'Lista PV'!$M$2:$M$826,"ATRASADO") -> 0 | C36: =COUNTIFS('Lista PV'!$B$2:$B$826,$A36,'Lista PV'!$M$2:$M$826,"POR VENCER") -> 0 | D36: =COUNTIFS('Lista PV'!$B$2:$B$826,$A36,'Lista PV'!$M$2:$M$826,"EN TIEMPO") -> 2 | E36: =COUNTIFS('Lista PV'!$B$2:$B$826,$A36,'Lista PV'!$M$2:$M$826,"REVISAR") -> 0 | F36: =COUNTIFS('Lista PV'!$B$2:$B$826,$A36,'Lista PV'!$M$2:$M$826,"REVISAR TE") -> 0 | G36: =SUM(B36:F36) -> 2
A37: MOTORES Y APARATOS ELECTRICOS DE DURANGO | B37: =COUNTIFS('Lista PV'!$B$2:$B$826,$A37,'Lista PV'!$M$2:$M$826,"ATRASADO") -> 0 | C37: =COUNTIFS('Lista PV'!$B$2:$B$826,$A37,'Lista PV'!$M$2:$M$826,"POR VENCER") -> 0 | D37: =COUNTIFS('Lista PV'!$B$2:$B$826,$A37,'Lista PV'!$M$2:$M$826,"EN TIEMPO") -> 0 | E37: =COUNTIFS('Lista PV'!$B$2:$B$826,$A37,'Lista PV'!$M$2:$M$826,"REVISAR") -> 0 | F37: =COUNTIFS('Lista PV'!$B$2:$B$826,$A37,'Lista PV'!$M$2:$M$826,"REVISAR TE") -> 0 | G37: =SUM(B37:F37) -> 0
A38: NOBEL AUTOMOTIVE TENNESSEE LLC | B38: =COUNTIFS('Lista PV'!$B$2:$B$826,$A38,'Lista PV'!$M$2:$M$826,"ATRASADO") -> 0 | C38: =COUNTIFS('Lista PV'!$B$2:$B$826,$A38,'Lista PV'!$M$2:$M$826,"POR VENCER") -> 0 | D38: =COUNTIFS('Lista PV'!$B$2:$B$826,$A38,'Lista PV'!$M$2:$M$826,"EN TIEMPO") -> 0 | E38: =COUNTIFS('Lista PV'!$B$2:$B$826,$A38,'Lista PV'!$M$2:$M$826,"REVISAR") -> 0 | F38: =COUNTIFS('Lista PV'!$B$2:$B$826,$A38,'Lista PV'!$M$2:$M$826,"REVISAR TE") -> 0 | G38: =SUM(B38:F38) -> 0
A39: SONOCO | B39: =COUNTIFS('Lista PV'!$B$2:$B$826,$A39,'Lista PV'!$M$2:$M$826,"ATRASADO") -> 0 | C39: =COUNTIFS('Lista PV'!$B$2:$B$826,$A39,'Lista PV'!$M$2:$M$826,"POR VENCER") -> 0 | D39: =COUNTIFS('Lista PV'!$B$2:$B$826,$A39,'Lista PV'!$M$2:$M$826,"EN TIEMPO") -> 0 | E39: =COUNTIFS('Lista PV'!$B$2:$B$826,$A39,'Lista PV'!$M$2:$M$826,"REVISAR") -> 0 | F39: =COUNTIFS('Lista PV'!$B$2:$B$826,$A39,'Lista PV'!$M$2:$M$826,"REVISAR TE") -> 0 | G39: =SUM(B39:F39) -> 0
A40: NOBEL AUTOMOTIVE MEXICO | B40: =COUNTIFS('Lista PV'!$B$2:$B$826,$A40,'Lista PV'!$M$2:$M$826,"ATRASADO") -> 0 | C40: =COUNTIFS('Lista PV'!$B$2:$B$826,$A40,'Lista PV'!$M$2:$M$826,"POR VENCER") -> 0 | D40: =COUNTIFS('Lista PV'!$B$2:$B$826,$A40,'Lista PV'!$M$2:$M$826,"EN TIEMPO") -> 0 | E40: =COUNTIFS('Lista PV'!$B$2:$B$826,$A40,'Lista PV'!$M$2:$M$826,"REVISAR") -> 0 | F40: =COUNTIFS('Lista PV'!$B$2:$B$826,$A40,'Lista PV'!$M$2:$M$826,"REVISAR TE") -> 0 | G40: =SUM(B40:F40) -> 0
... A48: COOPER-STANDARD AUTOMOTIVE INC. | B48: =COUNTIFS('Lista PV'!$B$2:$B$826,$A48,'Lista PV'!$M$2:$M$826,"ATRASADO") -> 0 | C48: =COUNTIFS('Lista PV'!$B$2:$B$826,$A48,'Lista PV'!$M$2:$M$826,"POR VENCER") -> 0 | D48: =COUNTIFS('Lista PV'!$B$2:$B$826,$A48,'Lista PV'!$M$2:$M$826,"EN TIEMPO") -> 0 | E48: =COUNTIFS('Lista PV'!$B$2:$B$826,$A48,'Lista PV'!$M$2:$M$826,"REVISAR") -> 0 | F48: =COUNTIFS('Lista PV'!$B$2:$B$826,$A48,'Lista PV'!$M$2:$M$826,"REVISAR TE") -> 1 | G48: =SUM(B48:F48) -> 1
A49: (Sin cliente capturado) | B49: =COUNTIFS('Lista PV'!$B$2:$B$826,"",'Lista PV'!$M$2:$M$826,"ATRASADO") -> 25 | C49: =COUNTIFS('Lista PV'!$B$2:$B$826,"",'Lista PV'!$M$2:$M$826,"POR VENCER") -> 0 | D49: =COUNTIFS('Lista PV'!$B$2:$B$826,"",'Lista PV'!$M$2:$M$826,"EN TIEMPO") -> 1 | E49: =COUNTIFS('Lista PV'!$B$2:$B$826,"",'Lista PV'!$M$2:$M$826,"REVISAR") -> 0 | F49: =COUNTIFS('Lista PV'!$B$2:$B$826,"",'Lista PV'!$M$2:$M$826,"REVISAR TE") -> 0 | G49: =SUM(B49:F49) -> 26
A50: TOTAL | B50: =SUM(B29:B49) -> 173 | C50: =SUM(C29:C49) -> 18 | D50: =SUM(D29:D49) -> 48 | E50: =SUM(E29:E49) -> 0 | F50: =SUM(F29:F49) -> 1 | G50: =SUM(G29:G49) -> 240
A51: Verificación contra sección 2 (debe ser 0): | G51: =G50-J7 -> 0

Sheet Lista PV
A1: PV | B1: Cliente | C1: Concepto | D1: Fecha PV | E1: Cantidad | F1: Fecha inicio | G1: TE (texto del PDF) | H1: TE (días) | I1: Fecha entrega estimada | J1: Dias para la entrega estimada | K1: días de atraso | L1: Embarque | M1: Estado | N1: Clave | P1: Archivo | Q1: fecha reprogramada de entrega
A2: PV 1290 | B2: HUTCHINSON TRANSFERENCIA DE FLUIDOS MEXICO | C2: FIXTURA INSPECCION ALUMINIO | GAGE 68612035 | D2: 46029 | E2: 1 | F2: 46029 | G2: 3 SEMANAS | H2: 21 | I2: =IF(AND(D2<>"",H2<>""),D2+H2,"") -> 46050 | J2: =I2-TODAY() -> -254 | K2: =IF(AND(L2="",ISNUMBER(IF(Q2<>"",Q2,I2))),IF(IF(Q2<>"",Q2,I2)<TODAY(),TODAY()-IF(Q2<>"",Q2,I2),""),"") | L2: x | M2: =IF(L2<>"","Entregado",IF(NOT(ISNUMBER(IF(Q2<>"",Q2,I2))),"REVISAR TE",IF(AND(ISNUMBER(Resumen!$B$3),IF(Q2<>"",Q2,I2)<Resumen!$B$3),"REVISAR",IF(IF(Q2<>"",Q2,I2)<TODAY(),"ATRASADO",IF(IF(Q2<>"",Q2,I2)-TODAY()<=2,"POR VENCER","EN TIEMPO"))))) -> Entregado | N2: FIX-NVO-01 | P2: PV1290.pdf
A3: PV 1291 | B3: HUTCHINSON TRANSFERENCIA DE FLUIDOS MEXICO | C3: VENTANA GAGE ALUMINIO | Reposición de torre y ventana NP 86793804 | D3: 46029 | E3: 1 | F3: 46029 | G3: INMEDIATO | H3: 0 | I3: =IF(AND(D3<>"",H3<>""),D3+H3,"") -> 46029 | J3: =I3-TODAY() -> -275 | K3: =IF(AND(L3="",ISNUMBER(IF(Q3<>"",Q3,I3))),IF(IF(Q3<>"",Q3,I3)<TODAY(),TODAY()-IF(Q3<>"",Q3,I3),""),"") | L3: x | M3: =IF(L3<>"","Entregado",IF(NOT(ISNUMBER(IF(Q3<>"",Q3,I3))),"REVISAR TE",IF(AND(ISNUMBER(Resumen!$B$3),IF(Q3<>"",Q3,I3)<Resumen!$B$3),"REVISAR",IF(IF(Q3<>"",Q3,I3)<TODAY(),"ATRASADO",IF(IF(Q3<>"",Q3,I3)-TODAY()<=2,"POR VENCER","EN TIEMPO"))))) -> Entregado | N3: FIX-RETR-04 | P3: PV1291.pdf
A4: PV 1292 | C4: MANDRIL CON TAPAS | MANDRIL 310042712 17-4PH ENDURECIDO | D4: 46029 | E4: 22 | F4: 46029 | G4: 3 A 4 SEMANAS | H4: 28 | I4: =IF(AND(D4<>"",H4<>""),D4+H4,"") -> 46057 | J4: =I4-TODAY() -> -247 | K4: =IF(AND(L4="",ISNUMBER(IF(Q4<>"",Q4,I4))),IF(IF(Q4<>"",Q4,I4)<TODAY(),TODAY()-IF(Q4<>"",Q4,I4),""),"") | L4: x | M4: =IF(L4<>"","Entregado",IF(NOT(ISNUMBER(IF(Q4<>"",Q4,I4))),"REVISAR TE",IF(AND(ISNUMBER(Resumen!$B$3),IF(Q4<>"",Q4,I4)<Resumen!$B$3),"REVISAR",IF(IF(Q4<>"",Q4,I4)<TODAY(),"ATRASADO",IF(IF(Q4<>"",Q4,I4)-TODAY()<=2,"POR VENCER","EN TIEMPO"))))) -> Entregado | N4: MAN-NVO-01 | P4: PV1292.pdf
A5: PV 1293 | B5: GRUPO AMERICAN INDUSTRIES | C5: MANDRIL SIN TAPAS | 18-715A | D5: 46031 | E5: 15 | F5: 46031 | G5: 3 SEMANAS | H5: 21 | I5: =IF(AND(D5<>"",H5<>""),D5+H5,"") -> 46052 | J5: =I5-TODAY() -> -252 | K5: =IF(AND(L5="",ISNUMBER(IF(Q5<>"",Q5,I5))),IF(IF(Q5<>"",Q5,I5)<TODAY(),TODAY()-IF(Q5<>"",Q5,I5),""),"") | L5: x | M5: =IF(L5<>"","Entregado",IF(NOT(ISNUMBER(IF(Q5<>"",Q5,I5))),"REVISAR TE",IF(AND(ISNUMBER(Resumen!$B$3),IF(Q5<>"",Q5,I5)<Resumen!$B$3),"REVISAR",IF(IF(Q5<>"",Q5,I5)<TODAY(),"ATRASADO",IF(IF(Q5<>"",Q5,I5)-TODAY()<=2,"POR VENCER","EN TIEMPO"))))) -> Entregado | N5: MAN-NVO-02 | P5: PV1293.pdf
A6: PV 1293 | B6: GRUPO AMERICAN INDUSTRIES | C6: MANDRIL SIN TAPAS | 18-716A | D6: 46031 | E6: 10 | F6: 46031 | G6: 3 SEMANAS | H6: 21 | I6: =IF(AND(D6<>"",H6<>""),D6+H6,"") -> 46052 | J6: =I6-TODAY() -> -252 | K6: =IF(AND(L6="",ISNUMBER(IF(Q6<>"",Q6,I6))),IF(IF(Q6<>"",Q6,I6)<TODAY(),TODAY()-IF(Q6<>"",Q6,I6),""),"") | L6: x | M6: =IF(L6<>"","Entregado",IF(NOT(ISNUMBER(IF(Q6<>"",Q6,I6))),"REVISAR TE",IF(AND(ISNUMBER(Resumen!$B$3),IF(Q6<>"",Q6,I6)<Resumen!$B$3),"REVISAR",IF(IF(Q6<>"",Q6,I6)<TODAY(),"ATRASADO",IF(IF(Q6<>"",Q6,I6)-TODAY()<=2,"POR VENCER","EN TIEMPO"))))) -> Entregado | N6: MAN-NVO-02 | P6: PV1293.pdf
A7: PV 1294 | B7: TOYODA GOSEI RUBBER MEXICO | C7: MANDRIL CON TAPAS | G90A5-0E020 MANDREL | D7: 46031 | E7: 4 | F7: 46031 | G7: 5 SEMANAS | H7: 35 | I7: =IF(AND(D7<>"",H7<>""),D7+H7,"") -> 46066 | J7: =I7-TODAY() -> -238 | K7: =IF(AND(L7="",ISNUMBER(IF(Q7<>"",Q7,I7))),IF(IF(Q7<>"",Q7,I7)<TODAY(),TODAY()-IF(Q7<>"",Q7,I7),""),"") | L7: x | M7: =IF(L7<>"","Entregado",IF(NOT(ISNUMBER(IF(Q7<>"",Q7,I7))),"REVISAR TE",IF(AND(ISNUMBER(Resumen!$B$3),IF(Q7<>"",Q7,I7)<Resumen!$B$3),"REVISAR",IF(IF(Q7<>"",Q7,I7)<TODAY(),"ATRASADO",IF(IF(Q7<>"",Q7,I7)-TODAY()<=2,"POR VENCER","EN TIEMPO"))))) -> Entregado | N7: MAN-NVO-01 | P7: PV1294.pdf
A8: PV 1294 | B8: TOYODA GOSEI RUBBER MEXICO | C8: MANDRIL CON TAPAS | G90AB-0E010 MANDREL | D8: 46031 | E8: 4 | F8: 46031 | G8: 5 SEMANAS | H8: 35 | I8: =IF(AND(D8<>"",H8<>""),D8+H8,"") -> 46066 | J8: =I8-TODAY() -> -238 | K8: =IF(AND(L8="",ISNUMBER(IF(Q8<>"",Q8,I8))),IF(IF(Q8<>"",Q8,I8)<TODAY(),TODAY()-IF(Q8<>"",Q8,I8),""),"") | L8: x | M8: =IF(L8<>"","Entregado",IF(NOT(ISNUMBER(IF(Q8<>"",Q8,I8))),"REVISAR TE",IF(AND(ISNUMBER(Resumen!$B$3),IF(Q8<>"",Q8,I8)<Resumen!$B$3),"REVISAR",IF(IF(Q8<>"",Q8,I8)<TODAY(),"ATRASADO",IF(IF(Q8<>"",Q8,I8)-TODAY()<=2,"POR VENCER","EN TIEMPO"))))) -> Entregado | N8: MAN-NVO-01 | P8: PV1294.pdf
A9: PV 1294 | B9: TOYODA GOSEI RUBBER MEXICO | C9: MANDRIL CON TAPAS | 870B8-0E010 MANDREL HOSE 1 | D9: 46031 | E9: 4 | F9: 46031 | G9: 5 SEMANAS | H9: 35 | I9: =IF(AND(D9<>"",H9<>""),D9+H9,"") -> 46066 | J9: =I9-TODAY() -> -238 | K9: =IF(AND(L9="",ISNUMBER(IF(Q9<>"",Q9,I9))),IF(IF(Q9<>"",Q9,I9)<TODAY(),TODAY()-IF(Q9<>"",Q9,I9),""),"") | L9: x | M9: =IF(L9<>"","Entregado",IF(NOT(ISNUMBER(IF(Q9<>"",Q9,I9))),"REVISAR TE",IF(AND(ISNUMBER(Resumen!$B$3),IF(Q9<>"",Q9,I9)<Resumen!$B$3),"REVISAR",IF(IF(Q9<>"",Q9,I9)<TODAY(),"ATRASADO",IF(IF(Q9<>"",Q9,I9)-TODAY()<=2,"POR VENCER","EN TIEMPO"))))) -> Entregado | N9: MAN-NVO-01 | P9: PV1294.pdf
A10: PV 1294 | B10: TOYODA GOSEI RUBBER MEXICO | C10: MANDRIL CON TAPAS | 870B8-0E010 MANDREL HOSE 2 | D10: 46031 | E10: 4 | F10: 46031 | G10: 5 SEMANAS | H10: 35 | I10: =IF(AND(D10<>"",H10<>""),D10+H10,"") -> 46066 | J10: =I10-TODAY() -> -238 | K10: =IF(AND(L10="",ISNUMBER(IF(Q10<>"",Q10,I10))),IF(IF(Q10<>"",Q10,I10)<TODAY(),TODAY()-IF(Q10<>"",Q10,I10),""),"") | L10: x | M10: =IF(L10<>"","Entregado",IF(NOT(ISNUMBER(IF(Q10<>"",Q10,I10))),"REVISAR TE",IF(AND(ISNUMBER(Resumen!$B$3),IF(Q10<>"",Q10,I10)<Resumen!$B$3),"REVISAR",IF(IF(Q10<>"",Q10,I10)<TODAY(),"ATRASADO",IF(IF(Q10<>"",Q10,I10)-TODAY()<=2,"POR VENCER","EN TIEMPO"))))) -> Entregado | N10: MAN-NVO-01 | P10: PV1294.pdf
A11: PV 1294 | B11: TOYODA GOSEI RUBBER MEXICO | C11: MANDRIL CON TAPAS | 870B8-0E010 MANDREL HOSE 3 | D11: 46031 | E11: 4 | F11: 46031 | G11: 5 SEMANAS | H11: 35 | I11: =IF(AND(D11<>"",H11<>""),D11+H11,"") -> 46066 | J11: =I11-TODAY() -> -238 | K11: =IF(AND(L11="",ISNUMBER(IF(Q11<>"",Q11,I11))),IF(IF(Q11<>"",Q11,I11)<TODAY(),TODAY()-IF(Q11<>"",Q11,I11),""),"") | L11: x | M11: =IF(L11<>"","Entregado",IF(NOT(ISNUMBER(IF(Q11<>"",Q11,I11))),"REVISAR TE",IF(AND(ISNUMBER(Resumen!$B$3),IF(Q11<>"",Q11,I11)<Resumen!$B$3),"REVISAR",IF(IF(Q11<>"",Q11,I11)<TODAY(),"ATRASADO",IF(IF(Q11<>"",Q11,I11)-TODAY()<=2,"POR VENCER","EN TIEMPO"))))) -> Entregado | N11: MAN-NVO-01 | P11: PV1294.pdf
A12: PV 1294 | B12: TOYODA GOSEI RUBBER MEXICO | C12: MANDRIL CON TAPAS | G90AA-0E010 MANDREL HOSE 1 | D12: 46031 | E12: 4 | F12: 46031 | G12: 5 SEMANAS | H12: 35 | I12: =IF(AND(D12<>"",H12<>""),D12+H12,"") -> 46066 | J12: =I12-TODAY() -> -238 | K12: =IF(AND(L12="",ISNUMBER(IF(Q12<>"",Q12,I12))),IF(IF(Q12<>"",Q12,I12)<TODAY(),TODAY()-IF(Q12<>"",Q12,I12),""),"") | L12: x | M12: =IF(L12<>"","Entregado",IF(NOT(ISNUMBER(IF(Q12<>"",Q12,I12))),"REVISAR TE",IF(AND(ISNUMBER(Resumen!$B$3),IF(Q12<>"",Q12,I12)<Resumen!$B$3),"REVISAR",IF(IF(Q12<>"",Q12,I12)<TODAY(),"ATRASADO",IF(IF(Q12<>"",Q12,I12)-TODAY()<=2,"POR VENCER","EN TIEMPO"))))) -> Entregado | N12: MAN-NVO-01 | P12: PV1294.pdf
A13: PV 1294 | B13: TOYODA GOSEI RUBBER MEXICO | C13: MANDRIL CON TAPAS | G90AA-0E010 MANDREL HOSE 2 | D13: 46031 | E13: 4 | F13: 46031 | G13: 5 SEMANAS | H13: 35 | I13: =IF(AND(D13<>"",H13<>""),D13+H13,"") -> 46066 | J13: =I13-TODAY() -> -238 | K13: =IF(AND(L13="",ISNUMBER(IF(Q13<>"",Q13,I13))),IF(IF(Q13<>"",Q13,I13)<TODAY(),TODAY()-IF(Q13<>"",Q13,I13),""),"") | L13: x | M13: =IF(L13<>"","Entregado",IF(NOT(ISNUMBER(IF(Q13<>"",Q13,I13))),"REVISAR TE",IF(AND(ISNUMBER(Resumen!$B$3),IF(Q13<>"",Q13,I13)<Resumen!$B$3),"REVISAR",IF(IF(Q13<>"",Q13,I13)<TODAY(),"ATRASADO",IF(IF(Q13<>"",Q13,I13)-TODAY()<=2,"POR VENCER","EN TIEMPO"))))) -> Entregado | N13: MAN-NVO-01 | P13: PV1294.pdf
A14: PV 1294 | B14: TOYODA GOSEI RUBBER MEXICO | C14: MANDRIL CON TAPAS | 870B2-0E010 MANDREL HOSE 1 | D14: 46031 | E14: 4 | F14: 46031 | G14: 5 SEMANAS | H14: 35 | I14: =IF(AND(D14<>"",H14<>""),D14+H14,"") -> 46066 | J14: =I14-TODAY() -> -238 | K14: =IF(AND(L14="",ISNUMBER(IF(Q14<>"",Q14,I14))),IF(IF(Q14<>"",Q14,I14)<TODAY(),TODAY()-IF(Q14<>"",Q14,I14),""),"") | L14: x | M14: =IF(L14<>"","Entregado",IF(NOT(ISNUMBER(IF(Q14<>"",Q14,I14))),"REVISAR TE",IF(AND(ISNUMBER(Resumen!$B$3),IF(Q14<>"",Q14,I14)<Resumen!$B$3),"REVISAR",IF(IF(Q14<>"",Q14,I14)<TODAY(),"ATRASADO",IF(IF(Q14<>"",Q14,I14)-TODAY()<=2,"POR VENCER","EN TIEMPO"))))) -> Entregado | N14: MAN-NVO-01 | P14: PV1294.pdf
A15: PV 1294 | B15: TOYODA GOSEI RUBBER MEXICO | C15: MANDRIL CON TAPAS | 870B2-0E010 MANDREL HOSE 2 | D15: 46031 | E15: 4 | F15: 46031 | G15: 5 SEMANAS | H15: 35 | I15: =IF(AND(D15<>"",H15<>""),D15+H15,"") -> 46066 | J15: =I15-TODAY() -> -238 | K15: =IF(AND(L15="",ISNUMBER(IF(Q15<>"",Q15,I15))),IF(IF(Q15<>"",Q15,I15)<TODAY(),TODAY()-IF(Q15<>"",Q15,I15),""),"") | L15: x | M15: =IF(L15<>"","Entregado",IF(NOT(ISNUMBER(IF(Q15<>"",Q15,I15))),"REVISAR TE",IF(AND(ISNUMBER(Resumen!$B$3),IF(Q15<>"",Q15,I15)<Resumen!$B$3),"REVISAR",IF(IF(Q15<>"",Q15,I15)<TODAY(),"ATRASADO",IF(IF(Q15<>"",Q15,I15)-TODAY()<=2,"POR VENCER","EN TIEMPO"))))) -> Entregado | N15: MAN-NVO-01 | P15: PV1294.pdf
A16: PV 1294 | B16: TOYODA GOSEI RUBBER MEXICO | C16: MANDRIL CON TAPAS | 870B5-0E010 MANDREL HOSE 1 | D16: 46031 | E16: 4 | F16: 46031 | G16: 5 SEMANAS | H16: 35 | I16: =IF(AND(D16<>"",H16<>""),D16+H16,"") -> 46066 | J16: =I16-TODAY() -> -238 | K16: =IF(AND(L16="",ISNUMBER(IF(Q16<>"",Q16,I16))),IF(IF(Q16<>"",Q16,I16)<TODAY(),TODAY()-IF(Q16<>"",Q16,I16),""),"") | L16: x | M16: =IF(L16<>"","Entregado",IF(NOT(ISNUMBER(IF(Q16<>"",Q16,I16))),"REVISAR TE",IF(AND(ISNUMBER(Resumen!$B$3),IF(Q16<>"",Q16,I16)<Resumen!$B$3),"REVISAR",IF(IF(Q16<>"",Q16,I16)<TODAY(),"ATRASADO",IF(IF(Q16<>"",Q16,I16)-TODAY()<=2,"POR VENCER","EN TIEMPO"))))) -> Entregado | N16: MAN-NVO-01 | P16: PV1294.pdf
... A42: PV 1301 | B42: TOYODA GOSEI RUBBER MEXICO | C42: MANDRIL CON TAPAS | MANDRIL GH699-90830 | D42: 46038 | E42: 16 | F42: 46038 | G42: 2 A 3 SEMANAS | H42: 21 | I42: =IF(AND(D42<>"",H42<>""),D42+H42,"") -> 46059 | J42: =I42-TODAY() -> -245 | K42: =IF(AND(L42="",ISNUMBER(IF(Q42<>"",Q42,I42))),IF(IF(Q42<>"",Q42,I42)<TODAY(),TODAY()-IF(Q42<>"",Q42,I42),""),"") | L42: x | M42: =IF(L42<>"","Entregado",IF(NOT(ISNUMBER(IF(Q42<>"",Q42,I42))),"REVISAR TE",IF(AND(ISNUMBER(Resumen!$B$3),IF(Q42<>"",Q42,I42)<Resumen!$B$3),"REVISAR",IF(IF(Q42<>"",Q42,I42)<TODAY(),"ATRASADO",IF(IF(Q42<>"",Q42,I42)-TODAY()<=2,"POR VENCER","EN TIEMPO"))))) -> Entregado | N42: MAN-NVO-01 | P42: PV1301.pdf
A43: PV 1302 | C43: MANDRIL SIN TAPAS | MANDRIL NP LC34-8N029-CE (310044714) ENDURECIDO | D43: 46038 | E43: 71 | F43: 46038 | G43: 3 SEMANAS | H43: 21 | I43: =IF(AND(D43<>"",H43<>""),D43+H43,"") -> 46059 | J43: =I43-TODAY() -> -245 | K43: =IF(AND(L43="",ISNUMBER(IF(Q43<>"",Q43,I43))),IF(IF(Q43<>"",Q43,I43)<TODAY(),TODAY()-IF(Q43<>"",Q43,I43),""),"") | L43: x | M43: =IF(L43<>"","Entregado",IF(NOT(ISNUMBER(IF(Q43<>"",Q43,I43))),"REVISAR TE",IF(AND(ISNUMBER(Resumen!$B$3),IF(Q43<>"",Q43,I43)<Resumen!$B$3),"REVISAR",IF(IF(Q43<>"",Q43,I43)<TODAY(),"ATRASADO",IF(IF(Q43<>"",Q43,I43)-TODAY()<=2,"POR VENCER","EN TIEMPO"))))) -> Entregado | N43: MAN-NVO-02 | P43: PV1302.pdf
A44: PV 1303 | B44: HUTCHINSON TRANSFERENCIA DE FLUIDOS MEXICO | C44: RETRABAJO DE FIXTURA DE ALUMINIO | Cambio de ingenieria para el NP 68612040AD TUBE 1 | D44: 46038 | E44: 1 | F44: 46038 | G44: 3 SEMANAS | H44: 21 | I44: =IF(AND(D44<>"",H44<>""),D44+H44,"") -> 46059 | J44: =I44-TODAY() -> -245 | K44: =IF(AND(L44="",ISNUMBER(IF(Q44<>"",Q44,I44))),IF(IF(Q44<>"",Q44,I44)<TODAY(),TODAY()-IF(Q44<>"",Q44,I44),""),"") | L44: x | M44: =IF(L44<>"","Entregado",IF(NOT(ISNUMBER(IF(Q44<>"",Q44,I44))),"REVISAR TE",IF(AND(ISNUMBER(Resumen!$B$3),IF(Q44<>"",Q44,I44)<Resumen!$B$3),"REVISAR",IF(IF(Q44<>"",Q44,I44)<TODAY(),"ATRASADO",IF(IF(Q44<>"",Q44,I44)-TODAY()<=2,"POR VENCER","EN TIEMPO"))))) -> Entregado | N44: FIX-RETR-08 | P44: PV1303.pdf
A45: PV 1303 | B45: HUTCHINSON TRANSFERENCIA DE FLUIDOS MEXICO | C45: RETRABAJO DE FIXTURA DE ALUMINIO | Cambio de ingenieria para el NP 68612040AD TUBE 2 | D45: 46038 | E45: 1 | F45: 46038 | G45: 3 SEMANAS | H45: 21 | I45: =IF(AND(D45<>"",H45<>""),D45+H45,"") -> 46059 | J45: =I45-TODAY() -> -245 | K45: =IF(AND(L45="",ISNUMBER(IF(Q45<>"",Q45,I45))),IF(IF(Q45<>"",Q45,I45)<TODAY(),TODAY()-IF(Q45<>"",Q45,I45),""),"") | L45: x | M45: =IF(L45<>"","Entregado",IF(NOT(ISNUMBER(IF(Q45<>"",Q45,I45))),"REVISAR TE",IF(AND(ISNUMBER(Resumen!$B$3),IF(Q45<>"",Q45,I45)<Resumen!$B$3),"REVISAR",IF(IF(Q45<>"",Q45,I45)<TODAY(),"ATRASADO",IF(IF(Q45<>"",Q45,I45)-TODAY()<=2,"POR VENCER","EN TIEMPO"))))) -> Entregado | N45: FIX-RETR-08 | P45: PV1303.pdf
A46: PV 1303 | B46: HUTCHINSON TRANSFERENCIA DE FLUIDOS MEXICO | C46: RETRABAJO DE FIXTURA DE ALUMINIO | Cambio de ingenieria para el NP 68612040AD TUBO RECTO | D46: 46038 | E46: 1 | F46: 46038 | G46: 3 SEMANAS | H46: 21 | I46: =IF(AND(D46<>"",H46<>""),D46+H46,"") -> 46059 | J46: =I46-TODAY() -> -245 | K46: =IF(AND(L46="",ISNUMBER(IF(Q46<>"",Q46,I46))),IF(IF(Q46<>"",Q46,I46)<TODAY(),TODAY()-IF(Q46<>"",Q46,I46),""),"") | L46: x | M46: =IF(L46<>"","Entregado",IF(NOT(ISNUMBER(IF(Q46<>"",Q46,I46))),"REVISAR TE",IF(AND(ISNUMBER(Resumen!$B$3),IF(Q46<>"",Q46,I46)<Resumen!$B$3),"REVISAR",IF(IF(Q46<>"",Q46,I46)<TODAY(),"ATRASADO",IF(IF(Q46<>"",Q46,I46)-TODAY()<=2,"POR VENCER","EN TIEMPO"))))) -> Entregado | N46: FIX-RETR-08 | P46: PV1303.pdf
A47: PV 1305 | B47: TRISTONE FLOWTECH MEXICO | C47: MANDRIL CON TAPAS | Mandril 53041769 TEMPLADO | D47: 46042 | E47: 1 | F47: 46042 | G47: 1 SEMANA | H47: 7 | I47: =IF(AND(D47<>"",H47<>""),D47+H47,"") -> 46049 | J47: =I47-TODAY() -> -255 | K47: =IF(AND(L47="",ISNUMBER(IF(Q47<>"",Q47,I47))),IF(IF(Q47<>"",Q47,I47)<TODAY(),TODAY()-IF(Q47<>"",Q47,I47),""),"") | L47: x | M47: =IF(L47<>"","Entregado",IF(NOT(ISNUMBER(IF(Q47<>"",Q47,I47))),"REVISAR TE",IF(AND(ISNUMBER(Resumen!$B$3),IF(Q47<>"",Q47,I47)<Resumen!$B$3),"REVISAR",IF(IF(Q47<>"",Q47,I47)<TODAY(),"ATRASADO",IF(IF(Q47<>"",Q47,I47)-TODAY()<=2,"POR VENCER","EN TIEMPO"))))) -> Entregado | N47: MAN-NVO-01 | P47: PV1305.pdf
A48: PV 1305 | B48: TRISTONE FLOWTECH MEXICO | C48: SERVICIO TEMPLE | LOTE DE TRATAMIENTO TERMICO | D48: 46042 | E48: 1 | F48: 46042 | G48: 1 SEMANA | H48: 7 | I48: =IF(AND(D48<>"",H48<>""),D48+H48,"") -> 46049 | J48: =I48-TODAY() -> -255 | K48: =IF(AND(L48="",ISNUMBER(IF(Q48<>"",Q48,I48))),IF(IF(Q48<>"",Q48,I48)<TODAY(),TODAY()-IF(Q48<>"",Q48,I48),""),"") | L48: x | M48: =IF(L48<>"","Entregado",IF(NOT(ISNUMBER(IF(Q48<>"",Q48,I48))),"REVISAR TE",IF(AND(ISNUMBER(Resumen!$B$3),IF(Q48<>"",Q48,I48)<Resumen!$B$3),"REVISAR",IF(IF(Q48<>"",Q48,I48)<TODAY(),"ATRASADO",IF(IF(Q48<>"",Q48,I48)-TODAY()<=2,"POR VENCER","EN TIEMPO"))))) -> Entregado | N48: SERV-TEMP-01 | P48: PV1305.pdf
A49: PV 1306 | B49: AKWEL ORIZABA MEXICO | C49: MANDRIL SIN TAPAS | MANDRIL P6016637A00 SS 17-4PH | D49: 46043 | E49: 3 | F49: 46043 | G49: 3 SEMANAS | H49: 21 | I49: =IF(AND(D49<>"",H49<>""),D49+H49,"") -> 46064 | J49: =I49-TODAY() -> -240 | K49: =IF(AND(L49="",ISNUMBER(IF(Q49<>"",Q49,I49))),IF(IF(Q49<>"",Q49,I49)<TODAY(),TODAY()-IF(Q49<>"",Q49,I49),""),"") | L49: x | M49: =IF(L49<>"","Entregado",IF(NOT(ISNUMBER(IF(Q49<>"",Q49,I49))),"REVISAR TE",IF(AND(ISNUMBER(Resumen!$B$3),IF(Q49<>"",Q49,I49)<Resumen!$B$3),"REVISAR",IF(IF(Q49<>"",Q49,I49)<TODAY(),"ATRASADO",IF(IF(Q49<>"",Q49,I49)-TODAY()<=2,"POR VENCER","EN TIEMPO"))))) -> Entregado | N49: MAN-NVO-02 | P49: PV1306.pdf
A50: PV 1307 | B50: AKWEL ORIZABA MEXICO | C50: MANDRIL SIN TAPAS | MANDRIL P6015721A00 | D50: 46043 | E50: 4 | F50: 46043 | G50: 2 SEMANAS | H50: 14 | I50: =IF(AND(D50<>"",H50<>""),D50+H50,"") -> 46057 | J50: =I50-TODAY() -> -247 | K50: =IF(AND(L50="",ISNUMBER(IF(Q50<>"",Q50,I50))),IF(IF(Q50<>"",Q50,I50)<TODAY(),TODAY()-IF(Q50<>"",Q50,I50),""),"") | L50: x | M50: =IF(L50<>"","Entregado",IF(NOT(ISNUMBER(IF(Q50<>"",Q50,I50))),"REVISAR TE",IF(AND(ISNUMBER(Resumen!$B$3),IF(Q50<>"",Q50,I50)<Resumen!$B$3),"REVISAR",IF(IF(Q50<>"",Q50,I50)<TODAY(),"ATRASADO",IF(IF(Q50<>"",Q50,I50)-TODAY()<=2,"POR VENCER","EN TIEMPO"))))) -> Entregado | N50: MAN-NVO-02 | P50: PV1307.pdf
A51: PV 1308 | B51: AKWEL ORIZABA MEXICO | C51: MANDRIL SIN TAPAS | MANDRIL P6017689A00 SS 17-4PH | D51: 46044 | E51: 8 | F51: 46044 | G51: 4 SEMANAS | H51: 28 | I51: =IF(AND(D51<>"",H51<>""),D51+H51,"") -> 46072 | J51: =I51-TODAY() -> -232 | K51: =IF(AND(L51="",ISNUMBER(IF(Q51<>"",Q51,I51))),IF(IF(Q51<>"",Q51,I51)<TODAY(),TODAY()-IF(Q51<>"",Q51,I51),""),"") | L51: x | M51: =IF(L51<>"","Entregado",IF(NOT(ISNUMBER(IF(Q51<>"",Q51,I51))),"REVISAR TE",IF(AND(ISNUMBER(Resumen!$B$3),IF(Q51<>"",Q51,I51)<Resumen!$B$3),"REVISAR",IF(IF(Q51<>"",Q51,I51)<TODAY(),"ATRASADO",IF(IF(Q51<>"",Q51,I51)-TODAY()<=2,"POR VENCER","EN TIEMPO"))))) -> Entregado | N51: MAN-NVO-02 | P51: PV1308.pdf
A52: PV 1309 | B52: AKWEL ORIZABA MEXICO | C52: MANDRIL CON TAPAS | MANDRIL M-86357015-A SS 17-4PH | D52: 46050 | E52: 48 | F52: 46050 | G52: 3 A 5 SEMANAS | H52: 35 | I52: =IF(AND(D52<>"",H52<>""),D52+H52,"") -> 46085 | J52: =I52-TODAY() -> -219 | K52: =IF(AND(L52="",ISNUMBER(IF(Q52<>"",Q52,I52))),IF(IF(Q52<>"",Q52,I52)<TODAY(),TODAY()-IF(Q52<>"",Q52,I52),""),"") | L52: x | M52: =IF(L52<>"","Entregado",IF(NOT(ISNUMBER(IF(Q52<>"",Q52,I52))),"REVISAR TE",IF(AND(ISNUMBER(Resumen!$B$3),IF(Q52<>"",Q52,I52)<Resumen!$B$3),"REVISAR",IF(IF(Q52<>"",Q52,I52)<TODAY(),"ATRASADO",IF(IF(Q52<>"",Q52,I52)-TODAY()<=2,"POR VENCER","EN TIEMPO"))))) -> Entregado | N52: MAN-NVO-01 | P52: PV1309.pdf
A53: PV 1309 | B53: AKWEL ORIZABA MEXICO | C53: MANDRIL CON TAPAS | MANDRIL M-86357015-B SS 17-4PH | D53: 46050 | E53: 48 | F53: 46050 | G53: 3 A 5 SEMANAS | H53: 35 | I53: =IF(AND(D53<>"",H53<>""),D53+H53,"") -> 46085 | J53: =I53-TODAY() -> -219 | K53: =IF(AND(L53="",ISNUMBER(IF(Q53<>"",Q53,I53))),IF(IF(Q53<>"",Q53,I53)<TODAY(),TODAY()-IF(Q53<>"",Q53,I53),""),"") | L53: x | M53: =IF(L53<>"","Entregado",IF(NOT(ISNUMBER(IF(Q53<>"",Q53,I53))),"REVISAR TE",IF(AND(ISNUMBER(Resumen!$B$3),IF(Q53<>"",Q53,I53)<Resumen!$B$3),"REVISAR",IF(IF(Q53<>"",Q53,I53)<TODAY(),"ATRASADO",IF(IF(Q53<>"",Q53,I53)-TODAY()<=2,"POR VENCER","EN TIEMPO"))))) -> Entregado | N53: MAN-NVO-01 | P53: PV1309.pdf
A54: PV 1311 | B54: TI AUTOMOTIVE REYNOSA | C54: FIXTURA INSPECCION ALUMINIO | BD GAUGE P21-M60109-00 Tubo A PARA BRAZER | D54: 46056 | E54: 1 | F54: 46056 | G54: 4 A 5 SEMANAS | H54: 35 | I54: =IF(AND(D54<>"",H54<>""),D54+H54,"") -> 46091 | J54: =I54-TODAY() -> -213 | K54: =IF(AND(L54="",ISNUMBER(IF(Q54<>"",Q54,I54))),IF(IF(Q54<>"",Q54,I54)<TODAY(),TODAY()-IF(Q54<>"",Q54,I54),""),"") | L54: x | M54: =IF(L54<>"","Entregado",IF(NOT(ISNUMBER(IF(Q54<>"",Q54,I54))),"REVISAR TE",IF(AND(ISNUMBER(Resumen!$B$3),IF(Q54<>"",Q54,I54)<Resumen!$B$3),"REVISAR",IF(IF(Q54<>"",Q54,I54)<TODAY(),"ATRASADO",IF(IF(Q54<>"",Q54,I54)-TODAY()<=2,"POR VENCER","EN TIEMPO"))))) -> Entregado | N54: FIX-NVO-01 | P54: PV1311.pdf
A55: PV 1312 | B55: TRISTONE FLOWTECH MEXICO | C55: MANDRIL | Marca de ensamblaje mandril 5304916 lado boss | D55: 46057 | E55: 44 | F55: 46057 | G55: 10 DÍAS | H55: 10 | I55: =IF(AND(D55<>"",H55<>""),D55+H55,"") -> 46067 | J55: =I55-TODAY() -> -237 | K55: =IF(AND(L55="",ISNUMBER(IF(Q55<>"",Q55,I55))),IF(IF(Q55<>"",Q55,I55)<TODAY(),TODAY()-IF(Q55<>"",Q55,I55),""),"") | L55: x | M55: =IF(L55<>"","Entregado",IF(NOT(ISNUMBER(IF(Q55<>"",Q55,I55))),"REVISAR TE",IF(AND(ISNUMBER(Resumen!$B$3),IF(Q55<>"",Q55,I55)<Resumen!$B$3),"REVISAR",IF(IF(Q55<>"",Q55,I55)<TODAY(),"ATRASADO",IF(IF(Q55<>"",Q55,I55)-TODAY()<=2,"POR VENCER","EN TIEMPO"))))) -> Entregado | N55: MAN-RETR-06 | P55: PV1312.pdf
... A63: PV 1316 | B63: AKWEL ORIZABA MEXICO | C63: SERVICIO DE ENVIO | SERVICIO DE EXPEDITDO GAUGE NP 85046133 (NEW 86357014) | D63: 46062 | E63: 1 | F63: 46062 | G63: 2 A 3 SEMANAS | H63: 21 | I63: =IF(AND(D63<>"",H63<>""),D63+H63,"") -> 46083 | J63: =I63-TODAY() -> -221 | K63: =IF(AND(L63="",ISNUMBER(IF(Q63<>"",Q63,I63))),IF(IF(Q63<>"",Q63,I63)<TODAY(),TODAY()-IF(Q63<>"",Q63,I63),""),"") | L63: x | M63: =IF(L63<>"","Entregado",IF(NOT(ISNUMBER(IF(Q63<>"",Q63,I63))),"REVISAR TE",IF(AND(ISNUMBER(Resumen!$B$3),IF(Q63<>"",Q63,I63)<Resumen!$B$3),"REVISAR",IF(IF(Q63<>"",Q63,I63)<TODAY(),"ATRASADO",IF(IF(Q63<>"",Q63,I63)-TODAY()<=2,"POR VENCER","EN TIEMPO"))))) -> Entregado | N63: SERV-ENV-01 | P63: PV1316.pdf
A64: PV 1318 | C64: MANDRIL CON TAPAS | MANDREL 310046868A | D64: 46064 | E64: 32 | F64: 46064 | G64: 4 A 5 SEMANAS | H64: 35 | I64: =IF(AND(D64<>"",H64<>""),D64+H64,"") -> 46099 | J64: =I64-TODAY() -> -205 | K64: =IF(AND(L64="",ISNUMBER(IF(Q64<>"",Q64,I64))),IF(IF(Q64<>"",Q64,I64)<TODAY(),TODAY()-IF(Q64<>"",Q64,I64),""),"") | L64: x | M64: =IF(L64<>"","Entregado",IF(NOT(ISNUMBER(IF(Q64<>"",Q64,I64))),"REVISAR TE",IF(AND(ISNUMBER(Resumen!$B$3),IF(Q64<>"",Q64,I64)<Resumen!$B$3),"REVISAR",IF(IF(Q64<>"",Q64,I64)<TODAY(),"ATRASADO",IF(IF(Q64<>"",Q64,I64)-TODAY()<=2,"POR VENCER","EN TIEMPO"))))) -> Entregado | N64: MAN-NVO-01 | P64: PV1318.pdf
A65: PV 1318 | C65: MANDRIL CON TAPAS | MANDREL 310046869A | D65: 46064 | E65: 32 | F65: 46064 | G65: 4 A 5 SEMANAS | H65: 35 | I65: =IF(AND(D65<>"",H65<>""),D65+H65,"") -> 46099 | J65: =I65-TODAY() -> -205 | K65: =IF(AND(L65="",ISNUMBER(IF(Q65<>"",Q65,I65))),IF(IF(Q65<>"",Q65,I65)<TODAY(),TODAY()-IF(Q65<>"",Q65,I65),""),"") | L65: x | M65: =IF(L65<>"","Entregado",IF(NOT(ISNUMBER(IF(Q65<>"",Q65,I65))),"REVISAR TE",IF(AND(ISNUMBER(Resumen!$B$3),IF(Q65<>"",Q65,I65)<Resumen!$B$3),"REVISAR",IF(IF(Q65<>"",Q65,I65)<TODAY(),"ATRASADO",IF(IF(Q65<>"",Q65,I65)-TODAY()<=2,"POR VENCER","EN TIEMPO"))))) -> Entregado | N65: MAN-NVO-01 | P65: PV1318.pdf
A66: PV 1318 | C66: MANDRIL CON TAPAS | MANDREL 310043947A | D66: 46064 | E66: 49 | F66: 46064 | G66: 4 A 5 SEMANAS | H66: 35 | I66: =IF(AND(D66<>"",H66<>""),D66+H66,"") -> 46099 | J66: =I66-TODAY() -> -205 | K66: =IF(AND(L66="",ISNUMBER(IF(Q66<>"",Q66,I66))),IF(IF(Q66<>"",Q66,I66)<TODAY(),TODAY()-IF(Q66<>"",Q66,I66),""),"") | L66: x | M66: =IF(L66<>"","Entregado",IF(NOT(ISNUMBER(IF(Q66<>"",Q66,I66))),"REVISAR TE",IF(AND(ISNUMBER(Resumen!$B$3),IF(Q66<>"",Q66,I66)<Resumen!$B$3),"REVISAR",IF(IF(Q66<>"",Q66,I66)<TODAY(),"ATRASADO",IF(IF(Q66<>"",Q66,I66)-TODAY()<=2,"POR VENCER","EN TIEMPO"))))) -> Entregado | N66: MAN-NVO-01 | P66: PV1318.pdf
A67: PV 1318 | C67: MANDRIL CON TAPAS | MANDREL 310043948A | D67: 46064 | E67: 49 | F67: 46064 | G67: 4 A 5 SEMANAS | H67: 35 | I67: =IF(AND(D67<>"",H67<>""),D67+H67,"") -> 46099 | J67: =I67-TODAY() -> -205 | K67: =IF(AND(L67="",ISNUMBER(IF(Q67<>"",Q67,I67))),IF(IF(Q67<>"",Q67,I67)<TODAY(),TODAY()-IF(Q67<>"",Q67,I67),""),"") | L67: x | M67: =IF(L67<>"","Entregado",IF(NOT(ISNUMBER(IF(Q67<>"",Q67,I67))),"REVISAR TE",IF(AND(ISNUMBER(Resumen!$B$3),IF(Q67<>"",Q67,I67)<Resumen!$B$3),"REVISAR",IF(IF(Q67<>"",Q67,I67)<TODAY(),"ATRASADO",IF(IF(Q67<>"",Q67,I67)-TODAY()<=2,"POR VENCER","EN TIEMPO"))))) -> Entregado | N67: MAN-NVO-01 | P67: PV1318.pdf
A68: PV 1319 | B68: TRISTONE FLOWTECH MEXICO | C68: RETRABAJO DE FIXTURA DE ALUMINIO | NUEVA VENTANA DE INSPECCIÓN DE ESTAMPADO NP 5A67548 | D68: 46064 | E68: 1 | F68: 46064 | G68: TBD | I68: =IF(AND(D68<>"",H68<>""),D68+H68,"") | J68: =I68-TODAY() -> #VALUE! | K68: =IF(AND(L68="",ISNUMBER(IF(Q68<>"",Q68,I68))),IF(IF(Q68<>"",Q68,I68)<TODAY(),TODAY()-IF(Q68<>"",Q68,I68),""),"") | L68: x | M68: =IF(L68<>"","Entregado",IF(NOT(ISNUMBER(IF(Q68<>"",Q68,I68))),"REVISAR TE",IF(AND(ISNUMBER(Resumen!$B$3),IF(Q68<>"",Q68,I68)<Resumen!$B$3),"REVISAR",IF(IF(Q68<>"",Q68,I68)<TODAY(),"ATRASADO",IF(IF(Q68<>"",Q68,I68)-TODAY()<=2,"POR VENCER","EN TIEMPO"))))) -> Entregado | N68: FIX-RETR-08 | P68: PV1319.pdf
A69: PV 1319 | B69: TRISTONE FLOWTECH MEXICO | C69: RETRABAJO DE FIXTURA DE ALUMINIO | NUEVA VENTANA DE INSPECCIÓN DE ESTAMPADO NP 5A67564 | D69: 46064 | E69: 1 | F69: 46064 | G69: TBD | I69: =IF(AND(D69<>"",H69<>""),D69+H69,"") | J69: =I69-TODAY() -> #VALUE! | K69: =IF(AND(L69="",ISNUMBER(IF(Q69<>"",Q69,I69))),IF(IF(Q69<>"",Q69,I69)<TODAY(),TODAY()-IF(Q69<>"",Q69,I69),""),"") | L69: x | M69: =IF(L69<>"","Entregado",IF(NOT(ISNUMBER(IF(Q69<>"",Q69,I69))),"REVISAR TE",IF(AND(ISNUMBER(Resumen!$B$3),IF(Q69<>"",Q69,I69)<Resumen!$B$3),"REVISAR",IF(IF(Q69<>"",Q69,I69)<TODAY(),"ATRASADO",IF(IF(Q69<>"",Q69,I69)-TODAY()<=2,"POR VENCER","EN TIEMPO"))))) -> Entregado | N69: FIX-RETR-08 | P69: PV1319.pdf
A70: PV 1319 | B70: TRISTONE FLOWTECH MEXICO | C70: RETRABAJO DE FIXTURA DE ALUMINIO | NUEVA VENTANA DE INSPECCIÓN DE ESTAMPADO NP 5A67574 | D70: 46064 | E70: 1 | F70: 46064 | G70: TBD | I70: =IF(AND(D70<>"",H70<>""),D70+H70,"") | J70: =I70-TODAY() -> #VALUE! | K70: =IF(AND(L70="",ISNUMBER(IF(Q70<>"",Q70,I70))),IF(IF(Q70<>"",Q70,I70)<TODAY(),TODAY()-IF(Q70<>"",Q70,I70),""),"") | L70: x | M70: =IF(L70<>"","Entregado",IF(NOT(ISNUMBER(IF(Q70<>"",Q70,I70))),"REVISAR TE",IF(AND(ISNUMBER(Resumen!$B$3),IF(Q70<>"",Q70,I70)<Resumen!$B$3),"REVISAR",IF(IF(Q70<>"",Q70,I70)<TODAY(),"ATRASADO",IF(IF(Q70<>"",Q70,I70)-TODAY()<=2,"POR VENCER","EN TIEMPO"))))) -> Entregado | N70: FIX-RETR-08 | P70: PV1319.pdf
A71: PV 1319 | B71: TRISTONE FLOWTECH MEXICO | C71: RETRABAJO DE FIXTURA DE ALUMINIO | NUEVA VENTANA DE INSPECCIÓN DE ESTAMPADO NP 5A67592 | D71: 46064 | E71: 1 | F71: 46064 | G71: TBD | I71: =IF(AND(D71<>"",H71<>""),D71+H71,"") | J71: =I71-TODAY() -> #VALUE! | K71: =IF(AND(L71="",ISNUMBER(IF(Q71<>"",Q71,I71))),IF(IF(Q71<>"",Q71,I71)<TODAY(),TODAY()-IF(Q71<>"",Q71,I71),""),"") | L71: x | M71: =IF(L71<>"","Entregado",IF(NOT(ISNUMBER(IF(Q71<>"",Q71,I71))),"REVISAR TE",IF(AND(ISNUMBER(Resumen!$B$3),IF(Q71<>"",Q71,I71)<Resumen!$B$3),"REVISAR",IF(IF(Q71<>"",Q71,I71)<TODAY(),"ATRASADO",IF(IF(Q71<>"",Q71,I71)-TODAY()<=2,"POR VENCER","EN TIEMPO"))))) -> Entregado | N71: FIX-RETR-08 | P71: PV1319.pdf
A72: PV 1319 | B72: TRISTONE FLOWTECH MEXICO | C72: RETRABAJO DE FIXTURA DE ALUMINIO | NUEVA VENTANA DE INSPECCIÓN DE ESTAMPADO NP 5A7FC30 | D72: 46064 | E72: 1 | F72: 46064 | G72: TBD | I72: =IF(AND(D72<>"",H72<>""),D72+H72,"") | J72: =I72-TODAY() -> #VALUE! | K72: =IF(AND(L72="",ISNUMBER(IF(Q72<>"",Q72,I72))),IF(IF(Q72<>"",Q72,I72)<TODAY(),TODAY()-IF(Q72<>"",Q72,I72),""),"") | L72: x | M72: =IF(L72<>"","Entregado",IF(NOT(ISNUMBER(IF(Q72<>"",Q72,I72))),"REVISAR TE",IF(AND(ISNUMBER(Resumen!$B$3),IF(Q72<>"",Q72,I72)<Resumen!$B$3),"REVISAR",IF(IF(Q72<>"",Q72,I72)<TODAY(),"ATRASADO",IF(IF(Q72<>"",Q72,I72)-TODAY()<=2,"POR VENCER","EN TIEMPO"))))) -> Entregado | N72: FIX-RETR-08 | P72: PV1319.pdf
...
